<?xml version="1.0"?>
<!-- =================================================================================== -->
<!-- |    This document was autogenerated by xacro from /home/swimming/dev_ws/src/ros2-navigation-examples/bocbot/urdf/bocbot.urdf.xacro | -->
<!-- |    EDITING THIS FILE BY HAND IS NOT RECOMMENDED                                 | -->
<!-- =================================================================================== -->
<robot name="bocbot">

  <link name="robot_footprint" />
  <joint name="robot_footprint_joint" type="fixed">
    <origin rpy="0 0 0" xyz="0 0 0" />
    <parent link="robot_footprint" />
    <child link="chassis" />
  </joint>
  <link name="chassis">
    <pose>0 0 0.1 0 0 0</pose>
    <inertial>
      <mass value="15.0" />
      <origin rpy=" 0 0 0" xyz="0.0 0 0" />
      <inertia ixx="0.1" ixy="0" ixz="0" iyy="0.1" iyz="0" izz="0.1" />
    </inertial>
    <collision name="collision">
      <origin rpy=" 0 0 0" xyz="0 0 0" />
      <geometry>
        <box size=".4 .2 .1" />
      </geometry>
    </collision>
    <visual name="chassis_visual">
      <origin rpy=" 0 0 0" xyz="0 0 0" />
      <geometry>
        <box size=".4 .2 .1" />
      </geometry>
    </visual>
  </link>
  <link name="front_left_wheel">
    <inertial>
      <mass value="5.0" />
      <origin rpy=" 0 1.5707 1.5707" xyz="0.0 0 0" />
      <inertia ixx="0.1" ixy="0" ixz="0" iyy="0.1" iyz="0" izz="0.1" />
    </inertial>
    <visual>
      <origin rpy=" 0 1.5707 1.5707" xyz="0.0 0 0" />
      <geometry>
        <cylinder length="0.05" radius="0.1" />
      </geometry>
    </visual>
    <collision>
      <origin rpy=" 0 1.5707 1.5707" xyz="0.0 0 0" />
      <geometry>
        <cylinder length="0.05" radius="0.1" />
      </geometry>
    </collision>
  </link>
  <joint name="front_left_wheel_joint" type="continuous">
    <origin rpy="0 0 0" xyz="0.12 0.15 0" />
    <child link="front_left_wheel" />
    <parent link="chassis" />
    <axis rpy="0 0 0" xyz="0 1 0" />
    <limit effort="10000" velocity="1000" />
    <dynamics damping="1.0" friction="1.0" />
  </joint>

  <link name="back_left_wheel">
    <inertial>
      <mass value="5.0" />
      <origin rpy=" 0 1.5707 1.5707" xyz="0.0 0 0" />
      <inertia ixx="0.1" ixy="0" ixz="0" iyy="0.1" iyz="0" izz="0.1" />
    </inertial>
    <visual>
      <origin rpy=" 0 1.5707 1.5707" xyz="0.0 0 0" />
      <geometry>
        <cylinder length="0.05" radius="0.1" />
      </geometry>
    </visual>
    <collision>
      <origin rpy=" 0 1.5707 1.5707" xyz="0.0 0 0" />
      <geometry>
        <cylinder length="0.05" radius="0.1" />
      </geometry>
    </collision>
  </link>
  <joint name="back_left_wheel_joint" type="continuous">
    <origin rpy="0 0 0" xyz="-0.12 0.15 0" />
    <child link="back_left_wheel" />
    <parent link="chassis" />
    <axis rpy="0 0 0" xyz="0 1 0" />
    <limit effort="10000" velocity="1000" />
    <dynamics damping="1.0" friction="1.0" />
  </joint>

  <link name="front_right_wheel">
    <inertial>
      <mass value="5.0" />
      <origin rpy=" 0 1.5707 1.5707" xyz="0.0 0 0" />
      <inertia ixx="0.1" ixy="0" ixz="0" iyy="0.1" iyz="0" izz="0.1" />
    </inertial>
    <visual>
      <origin rpy=" 0 1.5707 1.5707" xyz="0.0 0 0" />
      <geometry>
        <cylinder length="0.05" radius="0.1" />
      </geometry>
    </visual>
    <collision>
      <origin rpy=" 0 1.5707 1.5707" xyz="0.0 0 0" />
      <geometry>
        <cylinder length="0.05" radius="0.1" />
      </geometry>
    </collision>
  </link>
  <joint name="front_right_wheel_joint" type="continuous">
    <origin rpy="0 0 0" xyz="0.12 -0.15 0" />
    <child link="front_right_wheel" />
    <parent link="chassis" />
    <axis rpy="0 0 0" xyz="0 1 0" />
    <limit effort="10000" velocity="1000" />
    <dynamics damping="1.0" friction="1.0" />
  </joint>

  <link name="back_right_wheel">
    <inertial>
      <mass value="5.0" />
      <origin rpy=" 0 1.5707 1.5707" xyz="0.0 0 0" />
      <inertia ixx="0.1" ixy="0" ixz="0" iyy="0.1" iyz="0" izz="0.1" />
    </inertial>
    <visual>
      <origin rpy=" 0 1.5707 1.5707" xyz="0.0 0 0" />
      <geometry>
        <cylinder length="0.05" radius="0.1" />
      </geometry>
    </visual>
    <collision>
      <origin rpy=" 0 1.5707 1.5707" xyz="0.0 0 0" />
      <geometry>
        <cylinder length="0.05" radius="0.1" />
      </geometry>
    </collision>
  </link>
  <joint name="back_right_wheel_joint" type="continuous">
    <origin rpy="0 0 0" xyz="-0.12 -0.15 0" />
    <child link="back_right_wheel" />
    <parent link="chassis" />
    <axis rpy="0 0 0" xyz="0 1 0" />
    <limit effort="10000" velocity="1000" />
    <dynamics damping="1.0" friction="1.0" />
  </joint>

  <link name="camera">
    <inertial>
      <mass value="0.1" />
      <origin rpy=" 0 0 0" xyz="0.05 0.05 0.05" />
      <inertia ixx="1e-6" ixy="0" ixz="0" iyy="1e-6" iyz="0" izz="1e-6" />
    </inertial>
    <visual name="camera_visual">
      <origin rpy="0 0 0" xyz="0 0 0" />
      <geometry>
        <box size="0.05 0.05 0.05" />
      </geometry>
    </visual>
    <collision name="camera_colision">
      <origin rpy="0 0 0" xyz="0 0 0" />
      <geometry>
        <box size="0.05 0.05 0.05" />
      </geometry>
    </collision>
  </link>
  <joint name="camera_joint" type="fixed">
    <origin rpy="0 0 0" xyz="0.2 0 0" />
    <child link="camera" />
    <parent link="chassis" />
    <axis rpy="0 0 0" xyz="0 1 0" />
  </joint>

  <link name="hokuyo">
    <inertial>
      <mass value="1e-5" />
      <origin rpy=" 0 0 0" xyz="0 0 0" />
      <inertia ixx="1e-6" ixy="0" ixz="0" iyy="1e-6" iyz="0" izz="1e-6" />
    </inertial>
    <visual name="hokuyo_visual">
      <origin rpy="0 0 0" xyz="0 0 0" />
      <geometry>
        <!-- <mesh filename="$(find bocbot)/meshes/hokuyo.dae"/> -->
        <box size="0.05 0.05 0.05" />
      </geometry>
    </visual>
    <collision name="hokuyo_colision">
      <origin rpy="0 0 0" xyz="0 0 0" />
      <geometry>
        <box size="0.1 0.1 0.1" />
      </geometry>
    </collision>
  </link>
  <joint name="hokuyo_joint" type="fixed">
    <origin rpy="0 0 0" xyz="0.15 0 0.1" />
    <child link="hokuyo" />
    <parent link="chassis" />
    <axis rpy="0 0 0" xyz="0 1 0" />
  </joint>

  <gazebo reference="chassis">
    <material>Gazebo/Blue</material>
  </gazebo>
  <gazebo reference="camera">
    <material>Gazebo/Red</material>
  </gazebo>
  <gazebo reference="hokuyo">
    <material>Gazebo/Black</material>
  </gazebo>
</robot>